ERROR:TeleBot:Threaded polling exception: A request to the Telegram API was unsuccessful. Error code: 409. Description: Conflict: terminated by other getUpdates request; make sure that only one bot instance is running
ERROR:TeleBot:Exception traceback:
Traceback (most recent call last):
  File "/home/mika2/.cache/pypoetry/virtualenvs/telegram-bot-gago-5ebyI9Gw-py3.10/lib/python3.10/site-packages/telebot/__init__.py", line 1140, in __threaded_polling
    polling_thread.raise_exceptions()
  File "/home/mika2/.cache/pypoetry/virtualenvs/telegram-bot-gago-5ebyI9Gw-py3.10/lib/python3.10/site-packages/telebot/util.py", line 110, in raise_exceptions
    raise self.exception_info
  File "/home/mika2/.cache/pypoetry/virtualenvs/telegram-bot-gago-5ebyI9Gw-py3.10/lib/python3.10/site-packages/telebot/util.py", line 92, in run
    task(*args, **kwargs)
  File "/home/mika2/.cache/pypoetry/virtualenvs/telegram-bot-gago-5ebyI9Gw-py3.10/lib/python3.10/site-packages/telebot/__init__.py", line 661, in __retrieve_updates
    updates = self.get_updates(offset=(self.last_update_id + 1),
  File "/home/mika2/.cache/pypoetry/virtualenvs/telegram-bot-gago-5ebyI9Gw-py3.10/lib/python3.10/site-packages/telebot/__init__.py", line 633, in get_updates
    json_updates = apihelper.get_updates(
  File "/home/mika2/.cache/pypoetry/virtualenvs/telegram-bot-gago-5ebyI9Gw-py3.10/lib/python3.10/site-packages/telebot/apihelper.py", line 321, in get_updates
    return _make_request(token, method_url, params=payload)
  File "/home/mika2/.cache/pypoetry/virtualenvs/telegram-bot-gago-5ebyI9Gw-py3.10/lib/python3.10/site-packages/telebot/apihelper.py", line 164, in _make_request
    json_result = _check_result(method_name, result)
  File "/home/mika2/.cache/pypoetry/virtualenvs/telegram-bot-gago-5ebyI9Gw-py3.10/lib/python3.10/site-packages/telebot/apihelper.py", line 191, in _check_result
    raise ApiTelegramException(method_name, result, result_json)
telebot.apihelper.ApiTelegramException: A request to the Telegram API was unsuccessful. Error code: 409. Description: Conflict: terminated by other getUpdates request; make sure that only one bot instance is running

ERROR:__main__:Uncaught exception
Traceback (most recent call last):
  File "/home/mika2/.cache/pypoetry/virtualenvs/telegram-bot-gago-5ebyI9Gw-py3.10/lib/python3.10/site-packages/urllib3/connectionpool.py", line 537, in _make_request
    response = conn.getresponse()
  File "/home/mika2/.cache/pypoetry/virtualenvs/telegram-bot-gago-5ebyI9Gw-py3.10/lib/python3.10/site-packages/urllib3/connection.py", line 466, in getresponse
    httplib_response = super().getresponse()
  File "/usr/lib/python3.10/http/client.py", line 1375, in getresponse
    response.begin()
  File "/usr/lib/python3.10/http/client.py", line 318, in begin
    version, status, reason = self._read_status()
  File "/usr/lib/python3.10/http/client.py", line 279, in _read_status
    line = str(self.fp.readline(_MAXLINE + 1), "iso-8859-1")
  File "/usr/lib/python3.10/socket.py", line 705, in readinto
    return self._sock.recv_into(b)
  File "/usr/lib/python3.10/ssl.py", line 1303, in recv_into
    return self.read(nbytes, buffer)
  File "/usr/lib/python3.10/ssl.py", line 1159, in read
    return self._sslobj.read(len, buffer)
TimeoutError: The read operation timed out

The above exception was the direct cause of the following exception:

Traceback (most recent call last):
  File "/home/mika2/.cache/pypoetry/virtualenvs/telegram-bot-gago-5ebyI9Gw-py3.10/lib/python3.10/site-packages/requests/adapters.py", line 486, in send
    resp = conn.urlopen(
  File "/home/mika2/.cache/pypoetry/virtualenvs/telegram-bot-gago-5ebyI9Gw-py3.10/lib/python3.10/site-packages/urllib3/connectionpool.py", line 847, in urlopen
    retries = retries.increment(
  File "/home/mika2/.cache/pypoetry/virtualenvs/telegram-bot-gago-5ebyI9Gw-py3.10/lib/python3.10/site-packages/urllib3/util/retry.py", line 470, in increment
    raise reraise(type(error), error, _stacktrace)
  File "/home/mika2/.cache/pypoetry/virtualenvs/telegram-bot-gago-5ebyI9Gw-py3.10/lib/python3.10/site-packages/urllib3/util/util.py", line 39, in reraise
    raise value
  File "/home/mika2/.cache/pypoetry/virtualenvs/telegram-bot-gago-5ebyI9Gw-py3.10/lib/python3.10/site-packages/urllib3/connectionpool.py", line 793, in urlopen
    response = self._make_request(
  File "/home/mika2/.cache/pypoetry/virtualenvs/telegram-bot-gago-5ebyI9Gw-py3.10/lib/python3.10/site-packages/urllib3/connectionpool.py", line 539, in _make_request
    self._raise_timeout(err=e, url=url, timeout_value=read_timeout)
  File "/home/mika2/.cache/pypoetry/virtualenvs/telegram-bot-gago-5ebyI9Gw-py3.10/lib/python3.10/site-packages/urllib3/connectionpool.py", line 370, in _raise_timeout
    raise ReadTimeoutError(
urllib3.exceptions.ReadTimeoutError: HTTPSConnectionPool(host='api.telegram.org', port=443): Read timed out. (read timeout=25)

During handling of the above exception, another exception occurred:

Traceback (most recent call last):
  File "/home/mika2/Desktop/projects/telegram_bot_gago/telegram_bot_gago/main.py", line 317, in <module>
    bot.polling()
  File "/home/mika2/.cache/pypoetry/virtualenvs/telegram-bot-gago-5ebyI9Gw-py3.10/lib/python3.10/site-packages/telebot/__init__.py", line 1104, in polling
    self.__threaded_polling(non_stop=non_stop, interval=interval, timeout=timeout, long_polling_timeout=long_polling_timeout,
  File "/home/mika2/.cache/pypoetry/virtualenvs/telegram-bot-gago-5ebyI9Gw-py3.10/lib/python3.10/site-packages/telebot/__init__.py", line 1179, in __threaded_polling
    raise e
  File "/home/mika2/.cache/pypoetry/virtualenvs/telegram-bot-gago-5ebyI9Gw-py3.10/lib/python3.10/site-packages/telebot/__init__.py", line 1140, in __threaded_polling
    polling_thread.raise_exceptions()
  File "/home/mika2/.cache/pypoetry/virtualenvs/telegram-bot-gago-5ebyI9Gw-py3.10/lib/python3.10/site-packages/telebot/util.py", line 110, in raise_exceptions
    raise self.exception_info
  File "/home/mika2/.cache/pypoetry/virtualenvs/telegram-bot-gago-5ebyI9Gw-py3.10/lib/python3.10/site-packages/telebot/util.py", line 92, in run
    task(*args, **kwargs)
  File "/home/mika2/.cache/pypoetry/virtualenvs/telegram-bot-gago-5ebyI9Gw-py3.10/lib/python3.10/site-packages/telebot/__init__.py", line 661, in __retrieve_updates
    updates = self.get_updates(offset=(self.last_update_id + 1),
  File "/home/mika2/.cache/pypoetry/virtualenvs/telegram-bot-gago-5ebyI9Gw-py3.10/lib/python3.10/site-packages/telebot/__init__.py", line 633, in get_updates
    json_updates = apihelper.get_updates(
  File "/home/mika2/.cache/pypoetry/virtualenvs/telegram-bot-gago-5ebyI9Gw-py3.10/lib/python3.10/site-packages/telebot/apihelper.py", line 321, in get_updates
    return _make_request(token, method_url, params=payload)
  File "/home/mika2/.cache/pypoetry/virtualenvs/telegram-bot-gago-5ebyI9Gw-py3.10/lib/python3.10/site-packages/telebot/apihelper.py", line 158, in _make_request
    result = _get_req_session().request(
  File "/home/mika2/.cache/pypoetry/virtualenvs/telegram-bot-gago-5ebyI9Gw-py3.10/lib/python3.10/site-packages/requests/sessions.py", line 589, in request
    resp = self.send(prep, **send_kwargs)
  File "/home/mika2/.cache/pypoetry/virtualenvs/telegram-bot-gago-5ebyI9Gw-py3.10/lib/python3.10/site-packages/requests/sessions.py", line 703, in send
    r = adapter.send(request, **kwargs)
  File "/home/mika2/.cache/pypoetry/virtualenvs/telegram-bot-gago-5ebyI9Gw-py3.10/lib/python3.10/site-packages/requests/adapters.py", line 532, in send
    raise ReadTimeout(e, request=request)
requests.exceptions.ReadTimeout: HTTPSConnectionPool(host='api.telegram.org', port=443): Read timed out. (read timeout=25)
ERROR:__main__:Uncaught exception
Traceback (most recent call last):
  File "/home/mika2/.cache/pypoetry/virtualenvs/telegram-bot-gago-5ebyI9Gw-py3.10/lib/python3.10/site-packages/urllib3/connectionpool.py", line 537, in _make_request
    response = conn.getresponse()
  File "/home/mika2/.cache/pypoetry/virtualenvs/telegram-bot-gago-5ebyI9Gw-py3.10/lib/python3.10/site-packages/urllib3/connection.py", line 466, in getresponse
    httplib_response = super().getresponse()
  File "/usr/lib/python3.10/http/client.py", line 1375, in getresponse
    response.begin()
  File "/usr/lib/python3.10/http/client.py", line 318, in begin
    version, status, reason = self._read_status()
  File "/usr/lib/python3.10/http/client.py", line 279, in _read_status
    line = str(self.fp.readline(_MAXLINE + 1), "iso-8859-1")
  File "/usr/lib/python3.10/socket.py", line 705, in readinto
    return self._sock.recv_into(b)
  File "/usr/lib/python3.10/ssl.py", line 1303, in recv_into
    return self.read(nbytes, buffer)
  File "/usr/lib/python3.10/ssl.py", line 1159, in read
    return self._sslobj.read(len, buffer)
TimeoutError: The read operation timed out

The above exception was the direct cause of the following exception:

Traceback (most recent call last):
  File "/home/mika2/.cache/pypoetry/virtualenvs/telegram-bot-gago-5ebyI9Gw-py3.10/lib/python3.10/site-packages/requests/adapters.py", line 486, in send
    resp = conn.urlopen(
  File "/home/mika2/.cache/pypoetry/virtualenvs/telegram-bot-gago-5ebyI9Gw-py3.10/lib/python3.10/site-packages/urllib3/connectionpool.py", line 847, in urlopen
    retries = retries.increment(
  File "/home/mika2/.cache/pypoetry/virtualenvs/telegram-bot-gago-5ebyI9Gw-py3.10/lib/python3.10/site-packages/urllib3/util/retry.py", line 470, in increment
    raise reraise(type(error), error, _stacktrace)
  File "/home/mika2/.cache/pypoetry/virtualenvs/telegram-bot-gago-5ebyI9Gw-py3.10/lib/python3.10/site-packages/urllib3/util/util.py", line 39, in reraise
    raise value
  File "/home/mika2/.cache/pypoetry/virtualenvs/telegram-bot-gago-5ebyI9Gw-py3.10/lib/python3.10/site-packages/urllib3/connectionpool.py", line 793, in urlopen
    response = self._make_request(
  File "/home/mika2/.cache/pypoetry/virtualenvs/telegram-bot-gago-5ebyI9Gw-py3.10/lib/python3.10/site-packages/urllib3/connectionpool.py", line 539, in _make_request
    self._raise_timeout(err=e, url=url, timeout_value=read_timeout)
  File "/home/mika2/.cache/pypoetry/virtualenvs/telegram-bot-gago-5ebyI9Gw-py3.10/lib/python3.10/site-packages/urllib3/connectionpool.py", line 370, in _raise_timeout
    raise ReadTimeoutError(
urllib3.exceptions.ReadTimeoutError: HTTPSConnectionPool(host='api.telegram.org', port=443): Read timed out. (read timeout=25)

During handling of the above exception, another exception occurred:

Traceback (most recent call last):
  File "/home/mika2/Desktop/projects/telegram_bot_gago/telegram_bot_gago/main.py", line 316, in <module>
    bot.polling()
  File "/home/mika2/.cache/pypoetry/virtualenvs/telegram-bot-gago-5ebyI9Gw-py3.10/lib/python3.10/site-packages/telebot/__init__.py", line 1104, in polling
    self.__threaded_polling(non_stop=non_stop, interval=interval, timeout=timeout, long_polling_timeout=long_polling_timeout,
  File "/home/mika2/.cache/pypoetry/virtualenvs/telegram-bot-gago-5ebyI9Gw-py3.10/lib/python3.10/site-packages/telebot/__init__.py", line 1179, in __threaded_polling
    raise e
  File "/home/mika2/.cache/pypoetry/virtualenvs/telegram-bot-gago-5ebyI9Gw-py3.10/lib/python3.10/site-packages/telebot/__init__.py", line 1140, in __threaded_polling
    polling_thread.raise_exceptions()
  File "/home/mika2/.cache/pypoetry/virtualenvs/telegram-bot-gago-5ebyI9Gw-py3.10/lib/python3.10/site-packages/telebot/util.py", line 110, in raise_exceptions
    raise self.exception_info
  File "/home/mika2/.cache/pypoetry/virtualenvs/telegram-bot-gago-5ebyI9Gw-py3.10/lib/python3.10/site-packages/telebot/util.py", line 92, in run
    task(*args, **kwargs)
  File "/home/mika2/.cache/pypoetry/virtualenvs/telegram-bot-gago-5ebyI9Gw-py3.10/lib/python3.10/site-packages/telebot/__init__.py", line 661, in __retrieve_updates
    updates = self.get_updates(offset=(self.last_update_id + 1),
  File "/home/mika2/.cache/pypoetry/virtualenvs/telegram-bot-gago-5ebyI9Gw-py3.10/lib/python3.10/site-packages/telebot/__init__.py", line 633, in get_updates
    json_updates = apihelper.get_updates(
  File "/home/mika2/.cache/pypoetry/virtualenvs/telegram-bot-gago-5ebyI9Gw-py3.10/lib/python3.10/site-packages/telebot/apihelper.py", line 321, in get_updates
    return _make_request(token, method_url, params=payload)
  File "/home/mika2/.cache/pypoetry/virtualenvs/telegram-bot-gago-5ebyI9Gw-py3.10/lib/python3.10/site-packages/telebot/apihelper.py", line 158, in _make_request
    result = _get_req_session().request(
  File "/home/mika2/.cache/pypoetry/virtualenvs/telegram-bot-gago-5ebyI9Gw-py3.10/lib/python3.10/site-packages/requests/sessions.py", line 589, in request
    resp = self.send(prep, **send_kwargs)
  File "/home/mika2/.cache/pypoetry/virtualenvs/telegram-bot-gago-5ebyI9Gw-py3.10/lib/python3.10/site-packages/requests/sessions.py", line 703, in send
    r = adapter.send(request, **kwargs)
  File "/home/mika2/.cache/pypoetry/virtualenvs/telegram-bot-gago-5ebyI9Gw-py3.10/lib/python3.10/site-packages/requests/adapters.py", line 532, in send
    raise ReadTimeout(e, request=request)
requests.exceptions.ReadTimeout: HTTPSConnectionPool(host='api.telegram.org', port=443): Read timed out. (read timeout=25)
ERROR:__main__:Uncaught exception
Traceback (most recent call last):
  File "/home/mika2/.cache/pypoetry/virtualenvs/telegram-bot-gago-5ebyI9Gw-py3.10/lib/python3.10/site-packages/urllib3/connectionpool.py", line 537, in _make_request
    response = conn.getresponse()
  File "/home/mika2/.cache/pypoetry/virtualenvs/telegram-bot-gago-5ebyI9Gw-py3.10/lib/python3.10/site-packages/urllib3/connection.py", line 466, in getresponse
    httplib_response = super().getresponse()
  File "/usr/lib/python3.10/http/client.py", line 1375, in getresponse
    response.begin()
  File "/usr/lib/python3.10/http/client.py", line 318, in begin
    version, status, reason = self._read_status()
  File "/usr/lib/python3.10/http/client.py", line 279, in _read_status
    line = str(self.fp.readline(_MAXLINE + 1), "iso-8859-1")
  File "/usr/lib/python3.10/socket.py", line 705, in readinto
    return self._sock.recv_into(b)
  File "/usr/lib/python3.10/ssl.py", line 1303, in recv_into
    return self.read(nbytes, buffer)
  File "/usr/lib/python3.10/ssl.py", line 1159, in read
    return self._sslobj.read(len, buffer)
TimeoutError: The read operation timed out

The above exception was the direct cause of the following exception:

Traceback (most recent call last):
  File "/home/mika2/.cache/pypoetry/virtualenvs/telegram-bot-gago-5ebyI9Gw-py3.10/lib/python3.10/site-packages/requests/adapters.py", line 486, in send
    resp = conn.urlopen(
  File "/home/mika2/.cache/pypoetry/virtualenvs/telegram-bot-gago-5ebyI9Gw-py3.10/lib/python3.10/site-packages/urllib3/connectionpool.py", line 847, in urlopen
    retries = retries.increment(
  File "/home/mika2/.cache/pypoetry/virtualenvs/telegram-bot-gago-5ebyI9Gw-py3.10/lib/python3.10/site-packages/urllib3/util/retry.py", line 470, in increment
    raise reraise(type(error), error, _stacktrace)
  File "/home/mika2/.cache/pypoetry/virtualenvs/telegram-bot-gago-5ebyI9Gw-py3.10/lib/python3.10/site-packages/urllib3/util/util.py", line 39, in reraise
    raise value
  File "/home/mika2/.cache/pypoetry/virtualenvs/telegram-bot-gago-5ebyI9Gw-py3.10/lib/python3.10/site-packages/urllib3/connectionpool.py", line 793, in urlopen
    response = self._make_request(
  File "/home/mika2/.cache/pypoetry/virtualenvs/telegram-bot-gago-5ebyI9Gw-py3.10/lib/python3.10/site-packages/urllib3/connectionpool.py", line 539, in _make_request
    self._raise_timeout(err=e, url=url, timeout_value=read_timeout)
  File "/home/mika2/.cache/pypoetry/virtualenvs/telegram-bot-gago-5ebyI9Gw-py3.10/lib/python3.10/site-packages/urllib3/connectionpool.py", line 370, in _raise_timeout
    raise ReadTimeoutError(
urllib3.exceptions.ReadTimeoutError: HTTPSConnectionPool(host='api.telegram.org', port=443): Read timed out. (read timeout=25)

During handling of the above exception, another exception occurred:

Traceback (most recent call last):
  File "/home/mika2/Desktop/projects/telegram_bot_gago/telegram_bot_gago/main.py", line 313, in <module>
    bot.polling()
  File "/home/mika2/.cache/pypoetry/virtualenvs/telegram-bot-gago-5ebyI9Gw-py3.10/lib/python3.10/site-packages/telebot/__init__.py", line 1104, in polling
    self.__threaded_polling(non_stop=non_stop, interval=interval, timeout=timeout, long_polling_timeout=long_polling_timeout,
  File "/home/mika2/.cache/pypoetry/virtualenvs/telegram-bot-gago-5ebyI9Gw-py3.10/lib/python3.10/site-packages/telebot/__init__.py", line 1179, in __threaded_polling
    raise e
  File "/home/mika2/.cache/pypoetry/virtualenvs/telegram-bot-gago-5ebyI9Gw-py3.10/lib/python3.10/site-packages/telebot/__init__.py", line 1140, in __threaded_polling
    polling_thread.raise_exceptions()
  File "/home/mika2/.cache/pypoetry/virtualenvs/telegram-bot-gago-5ebyI9Gw-py3.10/lib/python3.10/site-packages/telebot/util.py", line 110, in raise_exceptions
    raise self.exception_info
  File "/home/mika2/.cache/pypoetry/virtualenvs/telegram-bot-gago-5ebyI9Gw-py3.10/lib/python3.10/site-packages/telebot/util.py", line 92, in run
    task(*args, **kwargs)
  File "/home/mika2/.cache/pypoetry/virtualenvs/telegram-bot-gago-5ebyI9Gw-py3.10/lib/python3.10/site-packages/telebot/__init__.py", line 661, in __retrieve_updates
    updates = self.get_updates(offset=(self.last_update_id + 1),
  File "/home/mika2/.cache/pypoetry/virtualenvs/telegram-bot-gago-5ebyI9Gw-py3.10/lib/python3.10/site-packages/telebot/__init__.py", line 633, in get_updates
    json_updates = apihelper.get_updates(
  File "/home/mika2/.cache/pypoetry/virtualenvs/telegram-bot-gago-5ebyI9Gw-py3.10/lib/python3.10/site-packages/telebot/apihelper.py", line 321, in get_updates
    return _make_request(token, method_url, params=payload)
  File "/home/mika2/.cache/pypoetry/virtualenvs/telegram-bot-gago-5ebyI9Gw-py3.10/lib/python3.10/site-packages/telebot/apihelper.py", line 158, in _make_request
    result = _get_req_session().request(
  File "/home/mika2/.cache/pypoetry/virtualenvs/telegram-bot-gago-5ebyI9Gw-py3.10/lib/python3.10/site-packages/requests/sessions.py", line 589, in request
    resp = self.send(prep, **send_kwargs)
  File "/home/mika2/.cache/pypoetry/virtualenvs/telegram-bot-gago-5ebyI9Gw-py3.10/lib/python3.10/site-packages/requests/sessions.py", line 703, in send
    r = adapter.send(request, **kwargs)
  File "/home/mika2/.cache/pypoetry/virtualenvs/telegram-bot-gago-5ebyI9Gw-py3.10/lib/python3.10/site-packages/requests/adapters.py", line 532, in send
    raise ReadTimeout(e, request=request)
requests.exceptions.ReadTimeout: HTTPSConnectionPool(host='api.telegram.org', port=443): Read timed out. (read timeout=25)
ERROR:__main__:Uncaught exception
Traceback (most recent call last):
  File "/home/mika2/.cache/pypoetry/virtualenvs/telegram-bot-gago-5ebyI9Gw-py3.10/lib/python3.10/site-packages/urllib3/connectionpool.py", line 537, in _make_request
    response = conn.getresponse()
  File "/home/mika2/.cache/pypoetry/virtualenvs/telegram-bot-gago-5ebyI9Gw-py3.10/lib/python3.10/site-packages/urllib3/connection.py", line 466, in getresponse
    httplib_response = super().getresponse()
  File "/usr/lib/python3.10/http/client.py", line 1375, in getresponse
    response.begin()
  File "/usr/lib/python3.10/http/client.py", line 318, in begin
    version, status, reason = self._read_status()
  File "/usr/lib/python3.10/http/client.py", line 279, in _read_status
    line = str(self.fp.readline(_MAXLINE + 1), "iso-8859-1")
  File "/usr/lib/python3.10/socket.py", line 705, in readinto
    return self._sock.recv_into(b)
  File "/usr/lib/python3.10/ssl.py", line 1303, in recv_into
    return self.read(nbytes, buffer)
  File "/usr/lib/python3.10/ssl.py", line 1159, in read
    return self._sslobj.read(len, buffer)
TimeoutError: The read operation timed out

The above exception was the direct cause of the following exception:

Traceback (most recent call last):
  File "/home/mika2/.cache/pypoetry/virtualenvs/telegram-bot-gago-5ebyI9Gw-py3.10/lib/python3.10/site-packages/requests/adapters.py", line 486, in send
    resp = conn.urlopen(
  File "/home/mika2/.cache/pypoetry/virtualenvs/telegram-bot-gago-5ebyI9Gw-py3.10/lib/python3.10/site-packages/urllib3/connectionpool.py", line 847, in urlopen
    retries = retries.increment(
  File "/home/mika2/.cache/pypoetry/virtualenvs/telegram-bot-gago-5ebyI9Gw-py3.10/lib/python3.10/site-packages/urllib3/util/retry.py", line 470, in increment
    raise reraise(type(error), error, _stacktrace)
  File "/home/mika2/.cache/pypoetry/virtualenvs/telegram-bot-gago-5ebyI9Gw-py3.10/lib/python3.10/site-packages/urllib3/util/util.py", line 39, in reraise
    raise value
  File "/home/mika2/.cache/pypoetry/virtualenvs/telegram-bot-gago-5ebyI9Gw-py3.10/lib/python3.10/site-packages/urllib3/connectionpool.py", line 793, in urlopen
    response = self._make_request(
  File "/home/mika2/.cache/pypoetry/virtualenvs/telegram-bot-gago-5ebyI9Gw-py3.10/lib/python3.10/site-packages/urllib3/connectionpool.py", line 539, in _make_request
    self._raise_timeout(err=e, url=url, timeout_value=read_timeout)
  File "/home/mika2/.cache/pypoetry/virtualenvs/telegram-bot-gago-5ebyI9Gw-py3.10/lib/python3.10/site-packages/urllib3/connectionpool.py", line 370, in _raise_timeout
    raise ReadTimeoutError(
urllib3.exceptions.ReadTimeoutError: HTTPSConnectionPool(host='api.telegram.org', port=443): Read timed out. (read timeout=25)

During handling of the above exception, another exception occurred:

Traceback (most recent call last):
  File "/home/mika2/Desktop/projects/telegram_bot_gago/telegram_bot_gago/main.py", line 313, in <module>
    bot.polling()
  File "/home/mika2/.cache/pypoetry/virtualenvs/telegram-bot-gago-5ebyI9Gw-py3.10/lib/python3.10/site-packages/telebot/__init__.py", line 1104, in polling
    self.__threaded_polling(non_stop=non_stop, interval=interval, timeout=timeout, long_polling_timeout=long_polling_timeout,
  File "/home/mika2/.cache/pypoetry/virtualenvs/telegram-bot-gago-5ebyI9Gw-py3.10/lib/python3.10/site-packages/telebot/__init__.py", line 1179, in __threaded_polling
    raise e
  File "/home/mika2/.cache/pypoetry/virtualenvs/telegram-bot-gago-5ebyI9Gw-py3.10/lib/python3.10/site-packages/telebot/__init__.py", line 1140, in __threaded_polling
    polling_thread.raise_exceptions()
  File "/home/mika2/.cache/pypoetry/virtualenvs/telegram-bot-gago-5ebyI9Gw-py3.10/lib/python3.10/site-packages/telebot/util.py", line 110, in raise_exceptions
    raise self.exception_info
  File "/home/mika2/.cache/pypoetry/virtualenvs/telegram-bot-gago-5ebyI9Gw-py3.10/lib/python3.10/site-packages/telebot/util.py", line 92, in run
    task(*args, **kwargs)
  File "/home/mika2/.cache/pypoetry/virtualenvs/telegram-bot-gago-5ebyI9Gw-py3.10/lib/python3.10/site-packages/telebot/__init__.py", line 661, in __retrieve_updates
    updates = self.get_updates(offset=(self.last_update_id + 1),
  File "/home/mika2/.cache/pypoetry/virtualenvs/telegram-bot-gago-5ebyI9Gw-py3.10/lib/python3.10/site-packages/telebot/__init__.py", line 633, in get_updates
    json_updates = apihelper.get_updates(
  File "/home/mika2/.cache/pypoetry/virtualenvs/telegram-bot-gago-5ebyI9Gw-py3.10/lib/python3.10/site-packages/telebot/apihelper.py", line 321, in get_updates
    return _make_request(token, method_url, params=payload)
  File "/home/mika2/.cache/pypoetry/virtualenvs/telegram-bot-gago-5ebyI9Gw-py3.10/lib/python3.10/site-packages/telebot/apihelper.py", line 158, in _make_request
    result = _get_req_session().request(
  File "/home/mika2/.cache/pypoetry/virtualenvs/telegram-bot-gago-5ebyI9Gw-py3.10/lib/python3.10/site-packages/requests/sessions.py", line 589, in request
    resp = self.send(prep, **send_kwargs)
  File "/home/mika2/.cache/pypoetry/virtualenvs/telegram-bot-gago-5ebyI9Gw-py3.10/lib/python3.10/site-packages/requests/sessions.py", line 703, in send
    r = adapter.send(request, **kwargs)
  File "/home/mika2/.cache/pypoetry/virtualenvs/telegram-bot-gago-5ebyI9Gw-py3.10/lib/python3.10/site-packages/requests/adapters.py", line 532, in send
    raise ReadTimeout(e, request=request)
requests.exceptions.ReadTimeout: HTTPSConnectionPool(host='api.telegram.org', port=443): Read timed out. (read timeout=25)
ERROR:__main__:Uncaught exception
Traceback (most recent call last):
  File "/home/mika2/.cache/pypoetry/virtualenvs/telegram-bot-gago-5ebyI9Gw-py3.10/lib/python3.10/site-packages/urllib3/connectionpool.py", line 537, in _make_request
    response = conn.getresponse()
  File "/home/mika2/.cache/pypoetry/virtualenvs/telegram-bot-gago-5ebyI9Gw-py3.10/lib/python3.10/site-packages/urllib3/connection.py", line 466, in getresponse
    httplib_response = super().getresponse()
  File "/usr/lib/python3.10/http/client.py", line 1375, in getresponse
    response.begin()
  File "/usr/lib/python3.10/http/client.py", line 318, in begin
    version, status, reason = self._read_status()
  File "/usr/lib/python3.10/http/client.py", line 279, in _read_status
    line = str(self.fp.readline(_MAXLINE + 1), "iso-8859-1")
  File "/usr/lib/python3.10/socket.py", line 705, in readinto
    return self._sock.recv_into(b)
  File "/usr/lib/python3.10/ssl.py", line 1303, in recv_into
    return self.read(nbytes, buffer)
  File "/usr/lib/python3.10/ssl.py", line 1159, in read
    return self._sslobj.read(len, buffer)
TimeoutError: The read operation timed out

The above exception was the direct cause of the following exception:

Traceback (most recent call last):
  File "/home/mika2/.cache/pypoetry/virtualenvs/telegram-bot-gago-5ebyI9Gw-py3.10/lib/python3.10/site-packages/requests/adapters.py", line 486, in send
    resp = conn.urlopen(
  File "/home/mika2/.cache/pypoetry/virtualenvs/telegram-bot-gago-5ebyI9Gw-py3.10/lib/python3.10/site-packages/urllib3/connectionpool.py", line 847, in urlopen
    retries = retries.increment(
  File "/home/mika2/.cache/pypoetry/virtualenvs/telegram-bot-gago-5ebyI9Gw-py3.10/lib/python3.10/site-packages/urllib3/util/retry.py", line 470, in increment
    raise reraise(type(error), error, _stacktrace)
  File "/home/mika2/.cache/pypoetry/virtualenvs/telegram-bot-gago-5ebyI9Gw-py3.10/lib/python3.10/site-packages/urllib3/util/util.py", line 39, in reraise
    raise value
  File "/home/mika2/.cache/pypoetry/virtualenvs/telegram-bot-gago-5ebyI9Gw-py3.10/lib/python3.10/site-packages/urllib3/connectionpool.py", line 793, in urlopen
    response = self._make_request(
  File "/home/mika2/.cache/pypoetry/virtualenvs/telegram-bot-gago-5ebyI9Gw-py3.10/lib/python3.10/site-packages/urllib3/connectionpool.py", line 539, in _make_request
    self._raise_timeout(err=e, url=url, timeout_value=read_timeout)
  File "/home/mika2/.cache/pypoetry/virtualenvs/telegram-bot-gago-5ebyI9Gw-py3.10/lib/python3.10/site-packages/urllib3/connectionpool.py", line 370, in _raise_timeout
    raise ReadTimeoutError(
urllib3.exceptions.ReadTimeoutError: HTTPSConnectionPool(host='api.telegram.org', port=443): Read timed out. (read timeout=25)

During handling of the above exception, another exception occurred:

Traceback (most recent call last):
  File "/home/mika2/Desktop/projects/telegram_bot_gago/telegram_bot_gago/main.py", line 313, in <module>
    bot.polling()
  File "/home/mika2/.cache/pypoetry/virtualenvs/telegram-bot-gago-5ebyI9Gw-py3.10/lib/python3.10/site-packages/telebot/__init__.py", line 1104, in polling
    self.__threaded_polling(non_stop=non_stop, interval=interval, timeout=timeout, long_polling_timeout=long_polling_timeout,
  File "/home/mika2/.cache/pypoetry/virtualenvs/telegram-bot-gago-5ebyI9Gw-py3.10/lib/python3.10/site-packages/telebot/__init__.py", line 1179, in __threaded_polling
    raise e
  File "/home/mika2/.cache/pypoetry/virtualenvs/telegram-bot-gago-5ebyI9Gw-py3.10/lib/python3.10/site-packages/telebot/__init__.py", line 1140, in __threaded_polling
    polling_thread.raise_exceptions()
  File "/home/mika2/.cache/pypoetry/virtualenvs/telegram-bot-gago-5ebyI9Gw-py3.10/lib/python3.10/site-packages/telebot/util.py", line 110, in raise_exceptions
    raise self.exception_info
  File "/home/mika2/.cache/pypoetry/virtualenvs/telegram-bot-gago-5ebyI9Gw-py3.10/lib/python3.10/site-packages/telebot/util.py", line 92, in run
    task(*args, **kwargs)
  File "/home/mika2/.cache/pypoetry/virtualenvs/telegram-bot-gago-5ebyI9Gw-py3.10/lib/python3.10/site-packages/telebot/__init__.py", line 661, in __retrieve_updates
    updates = self.get_updates(offset=(self.last_update_id + 1),
  File "/home/mika2/.cache/pypoetry/virtualenvs/telegram-bot-gago-5ebyI9Gw-py3.10/lib/python3.10/site-packages/telebot/__init__.py", line 633, in get_updates
    json_updates = apihelper.get_updates(
  File "/home/mika2/.cache/pypoetry/virtualenvs/telegram-bot-gago-5ebyI9Gw-py3.10/lib/python3.10/site-packages/telebot/apihelper.py", line 321, in get_updates
    return _make_request(token, method_url, params=payload)
  File "/home/mika2/.cache/pypoetry/virtualenvs/telegram-bot-gago-5ebyI9Gw-py3.10/lib/python3.10/site-packages/telebot/apihelper.py", line 158, in _make_request
    result = _get_req_session().request(
  File "/home/mika2/.cache/pypoetry/virtualenvs/telegram-bot-gago-5ebyI9Gw-py3.10/lib/python3.10/site-packages/requests/sessions.py", line 589, in request
    resp = self.send(prep, **send_kwargs)
  File "/home/mika2/.cache/pypoetry/virtualenvs/telegram-bot-gago-5ebyI9Gw-py3.10/lib/python3.10/site-packages/requests/sessions.py", line 703, in send
    r = adapter.send(request, **kwargs)
  File "/home/mika2/.cache/pypoetry/virtualenvs/telegram-bot-gago-5ebyI9Gw-py3.10/lib/python3.10/site-packages/requests/adapters.py", line 532, in send
    raise ReadTimeout(e, request=request)
requests.exceptions.ReadTimeout: HTTPSConnectionPool(host='api.telegram.org', port=443): Read timed out. (read timeout=25)
ERROR:__main__:Uncaught exception
Traceback (most recent call last):
  File "/home/mika2/Desktop/projects/telegram_bot_gago/telegram_bot_gago/main.py", line 313, in <module>
    bot.polling()
  File "/home/mika2/.cache/pypoetry/virtualenvs/telegram-bot-gago-5ebyI9Gw-py3.10/lib/python3.10/site-packages/telebot/__init__.py", line 1104, in polling
    self.__threaded_polling(non_stop=non_stop, interval=interval, timeout=timeout, long_polling_timeout=long_polling_timeout,
  File "/home/mika2/.cache/pypoetry/virtualenvs/telegram-bot-gago-5ebyI9Gw-py3.10/lib/python3.10/site-packages/telebot/__init__.py", line 1179, in __threaded_polling
    raise e
  File "/home/mika2/.cache/pypoetry/virtualenvs/telegram-bot-gago-5ebyI9Gw-py3.10/lib/python3.10/site-packages/telebot/__init__.py", line 1141, in __threaded_polling
    self.worker_pool.raise_exceptions()
  File "/home/mika2/.cache/pypoetry/virtualenvs/telegram-bot-gago-5ebyI9Gw-py3.10/lib/python3.10/site-packages/telebot/util.py", line 149, in raise_exceptions
    raise self.exception_info
  File "/home/mika2/.cache/pypoetry/virtualenvs/telegram-bot-gago-5ebyI9Gw-py3.10/lib/python3.10/site-packages/telebot/util.py", line 92, in run
    task(*args, **kwargs)
  File "/home/mika2/.cache/pypoetry/virtualenvs/telegram-bot-gago-5ebyI9Gw-py3.10/lib/python3.10/site-packages/telebot/__init__.py", line 7860, in _run_middlewares_and_handler
    result = handler['function'](message)
  File "/home/mika2/Desktop/projects/telegram_bot_gago/telegram_bot_gago/main.py", line 141, in handle_callback_query
    Սիրելի {bot.message.from_user.first_name} այժմ դուք գիտեք ինչպես են աշխատում ինստագրամի ալգորիթմները րիլսերի վրա
AttributeError: 'TeleBot' object has no attribute 'message'
